
Thread #3 was created
   at 0x........: clone (in /...libc...)
   by 0x........: ...
   by 0x........: pthread_create@GLIBC_ (in /lib/libpthread...)
   by 0x........: pthread_create@* (hg_intercepts.c:...)
   by 0x........: main (hg04_race.c:21)

Thread #2 was created
   at 0x........: clone (in /...libc...)
   by 0x........: ...
   by 0x........: pthread_create@GLIBC_ (in /lib/libpthread...)
   by 0x........: pthread_create@* (hg_intercepts.c:...)
   by 0x........: main (hg04_race.c:19)

Possible data race during read of size 4 at 0x........ by thread #3
   at 0x........: th (hg04_race.c:10)
   by 0x........: mythread_wrapper (hg_intercepts.c:...)
   by 0x........: ...
   by 0x........: ...
 This conflicts with a previous access by thread #2
   at 0x........: th (hg04_race.c:10)
   by 0x........: mythread_wrapper (hg_intercepts.c:...)
   by 0x........: ...
   by 0x........: ...
 Location 0x........ is 0 bytes inside local var "shared"
 declared at hg04_race.c:6, in frame #0 of thread 2

ERROR SUMMARY: 1 errors from 1 contexts (suppressed: 0 from 0)
