
Thread #3 was created
   at 0x........: clone (in /...libc...)
   by 0x........: ...
   by 0x........: pthread_create@GLIBC_ (in /lib/libpthread...)
   by 0x........: pthread_create@* (hg_intercepts.c:...)
   by 0x........: main (tc21_pthonce.c:86)

Thread #2 was created
   at 0x........: clone (in /...libc...)
   by 0x........: ...
   by 0x........: pthread_create@GLIBC_ (in /lib/libpthread...)
   by 0x........: pthread_create@* (hg_intercepts.c:...)
   by 0x........: main (tc21_pthonce.c:86)

Possible data race during read of size 4 at 0x........ by thread #3
   at 0x........: child (tc21_pthonce.c:74)
   by 0x........: mythread_wrapper (hg_intercepts.c:...)
   by 0x........: ...
   by 0x........: ...
 This conflicts with a previous access by thread #2
   at 0x........: child (tc21_pthonce.c:74)
   by 0x........: mythread_wrapper (hg_intercepts.c:...)
   by 0x........: ...
   by 0x........: ...
 Location 0x........ is 0 bytes inside local var "unprotected2"
 declared at tc21_pthonce.c:51, in frame #0 of thread 2

ERROR SUMMARY: 1 errors from 1 contexts (suppressed: 0 from 0)
